<?xml version="1.0"?>
<robot xmlns:xacro="http://www.ros.org/wiki/xacro">

    <link name="arm_base">
        <visual>
            <origin xyz="0 0 0" rpy="0 0 0"/>
            <geometry>
                <mesh filename="package://living_lab_robot_description/meshes/arm_base.dae" scale="1 1 1"/>
            </geometry>
        </visual>
        <collision>
            <origin xyz="0 0 0" rpy="0 0 0"/>
            <geometry>
                <mesh filename="package://living_lab_robot_description/meshes/arm_base.dae" scale="1 1 1"/>
            </geometry>
        </collision>
        <inertial>
            <origin xyz="0.0791 0 -0.0397" rpy="0 0 0"/>
            <mass value="0.25"/>
            <inertia ixx="0.000190" ixy="0.0" ixz="0.0" iyy="0.000508" iyz="0.0" izz="0.000434"/>
        </inertial>
    </link>

    <joint name="arm_base_joint" type="prismatic">
        <parent link="elevation_module"/>
        <child link="arm_base"/>
        <origin xyz="0.035 0 -0.0228" rpy="0 0 0"/>
        <axis xyz="1 0 0"/>
        <limit lower="-0.15" upper="0" velocity="1.0" effort="1000"/>
    </joint>
    <xacro:insert_position_transmission name="arm_base_joint" />

    <link name="arm_link1">
        <visual>
            <origin xyz="0 0 0" rpy="0 0 0"/>
            <geometry>
                <mesh filename="package://living_lab_robot_description/meshes/arm_link1.dae" scale="1 1 1"/>
            </geometry>
        </visual>
        <collision>
            <origin xyz="0 0 0" rpy="0 0 0"/>
            <geometry>
                <mesh filename="package://living_lab_robot_description/meshes/arm_link1.dae" scale="1 1 1"/>
            </geometry>
        </collision>
        <inertial>
            <origin xyz="0.0333 0 0" rpy="0 0 0"/>
            <mass value="0.39"/>
            <inertia ixx="0.000954" ixy="0.0" ixz="0.0" iyy="0.000283" iyz="0.0" izz="0.000954"/>
        </inertial>
    </link>

    <joint name="arm1_joint" type="revolute">
        <parent link="arm_base"/>
        <child link="arm_link1"/>
        <origin xyz="0.15612 0 -0.051215" rpy="0 0 0"/>
        <axis xyz="1 0 0"/>
        <limit lower="${-180/180*pi}" upper="${180/180*pi}" velocity="0.4" effort="1000"/>
    </joint>
    <xacro:insert_position_transmission name="arm1_joint" />

    <link name="arm_link2">
        <visual>
            <origin xyz="0 0 0" rpy="0 0 0"/>
            <geometry>
                <mesh filename="package://living_lab_robot_description/meshes/arm_link2.dae" scale="1 1 1"/>
            </geometry>
        </visual>
        <collision>
            <origin xyz="0 0 0" rpy="0 0 0"/>
            <geometry>
                <mesh filename="package://living_lab_robot_description/meshes/arm_link2.dae" scale="1 1 1"/>
            </geometry>
        </collision>
        <inertial>
            <origin xyz="0.1691 0 0.0089" rpy="0 0 0"/>
            <mass value="0.12"/>
            <inertia ixx="0.004171" ixy="0.0" ixz="-0.001476" iyy="0.014517" iyz="0.0" izz="0.016818"/>
        </inertial>
    </link>

    <joint name="arm2_joint" type="revolute">
        <parent link="arm_link1"/>
        <child link="arm_link2"/>
        <origin xyz="0.033 0 0" rpy="0 0 0"/>
        <axis xyz="0 1 0"/>
        <limit lower="${-95/180*pi}" upper="${95/180*pi}" velocity="0.4" effort="1000"/>
    </joint>
    <xacro:insert_position_transmission name="arm2_joint" />

    <link name="arm_link3">
        <visual>
            <origin xyz="0 0 0" rpy="0 0 0"/>
            <geometry>
                <mesh filename="package://living_lab_robot_description/meshes/arm_link3.dae" scale="1 1 1"/>
            </geometry>
        </visual>
        <collision>
            <origin xyz="0 0 0" rpy="0 0 0"/>
            <geometry>
                <mesh filename="package://living_lab_robot_description/meshes/arm_link3.dae" scale="1 1 1"/>
            </geometry>
        </collision>
        <inertial>
            <origin xyz="0.1137 0 -0.0419" rpy="0 0 0"/>
            <mass value="0.14"/>
            <inertia ixx="0.000363" ixy="0.000002" ixz="-0.000009" iyy="0.000832" iyz="0.0" izz="0.001036"/>
        </inertial>
    </link>

    <joint name="arm3_joint" type="revolute">
        <parent link="arm_link2"/>
        <child link="arm_link3"/>
        <origin xyz="0.264 0 0.030" rpy="0 0 0"/>
        <axis xyz="0 1 0"/>
        <limit lower="${-180/180*pi}" upper="${5/180*pi}" velocity="0.4" effort="1000"/>
    </joint>
    <xacro:insert_position_transmission name="arm3_joint" />

    <link name="arm_link4">
        <visual>
            <origin xyz="0 0 0" rpy="0 0 0"/>
            <geometry>
                <mesh filename="package://living_lab_robot_description/meshes/arm_link4.dae" scale="1 1 1"/>
            </geometry>
        </visual>
        <collision>
            <origin xyz="0 0 0" rpy="0 0 0"/>
            <geometry>
                <mesh filename="package://living_lab_robot_description/meshes/arm_link4.dae" scale="1 1 1"/>
            </geometry>
        </collision>
        <inertial>
            <origin xyz="0.0274 0.0 0.0" rpy="0 0 0"/>
            <mass value="0.20"/>
            <inertia ixx="0.000315" ixy="0.0" ixz="0.0" iyy="0.000096" iyz="0.0" izz="0.000315"/>
        </inertial>
    </link>

    <joint name="arm4_joint" type="revolute">
        <parent link="arm_link3"/>
        <child link="arm_link4"/>
        <origin xyz="0.231 0 -0.042" rpy="0 0 0"/>
        <axis xyz="1 0 0"/>
        <limit lower="${-180/180*pi}" upper="${180/180*pi}" velocity="0.4" effort="1000"/>
    </joint>
    <xacro:insert_position_transmission name="arm4_joint" />

    <link name="arm_link5">
        <visual>
            <origin xyz="0 0 0" rpy="0 0 0"/>
            <geometry>
                <mesh filename="package://living_lab_robot_description/meshes/arm_link5.dae" scale="1 1 1"/>
            </geometry>
        </visual>
        <collision>
            <origin xyz="0 0 0" rpy="0 0 0"/>
            <geometry>
                <mesh filename="package://living_lab_robot_description/meshes/arm_link5.dae" scale="1 1 1"/>
            </geometry>
        </collision>
        <inertial>
            <origin xyz="0.0608 0 0" rpy="0 0 0"/>
            <mass value="0.15"/>
            <inertia ixx="0.000427" ixy="0.0" ixz="0.0" iyy="0.000507" iyz="0.0" izz="0.000774"/>
        </inertial>
    </link>

    <joint name="arm5_joint" type="revolute">
        <parent link="arm_link4"/>
        <child link="arm_link5"/>
        <origin xyz="0.027 0 0" rpy="0 0 0"/>
        <axis xyz="0 1 0"/>
        <limit lower="${-95/180*pi}" upper="${95/180*pi}" velocity="0.4" effort="1000"/>
    </joint>
    <xacro:insert_position_transmission name="arm5_joint" /> -->

    <link name="arm_link6">
        <inertial>
            <origin xyz="0 0 0" rpy="0 0 0"/>
            <mass value="0.00001"/>
            <inertia ixx="0.00001" ixy="0.0" ixz="0.0" iyy="0.00001" iyz="0.0" izz="0.00001"/>
        </inertial>
    </link>

    <joint name="arm6_joint" type="revolute">
        <parent link="arm_link5"/>
        <child link="arm_link6"/>
        <origin xyz="0.123 0 0" rpy="0 0 0"/>
        <axis xyz="1 0 0"/>
        <limit lower="${-180/180*pi}" upper="${180/180*pi}" velocity="0.4" effort="1000"/>
    </joint>
    <xacro:insert_position_transmission name="arm6_joint" />
</robot>