<?xml version="1.0"?>
<robot xmlns:xacro="http://www.ros.org/wiki/xacro">

    <link name="arm_base">
        <visual>
            <origin xyz="0 0 0" rpy="0 0 0"/>
            <geometry>
                <mesh filename="package://living_lab_robot_description/meshes/arm_base.dae" scale="1 1 1"/>
            </geometry>
        </visual>
        <collision>
            <origin xyz="0 0 0" rpy="0 0 0"/>
            <geometry>
                <mesh filename="package://living_lab_robot_description/meshes/arm_base.dae" scale="1 1 1"/>
            </geometry>
        </collision>
        <inertial>
            <origin xyz="0.0784 0 -0.0345" rpy="0 0 0"/>
            <mass value="0.4997"/>
            <inertia ixx="0.000431" ixy="0.0" ixz="0.0" iyy="0.001305" iyz="0.0" izz="0.001120"/>
        </inertial>
    </link>

    <joint name="arm_base_joint" type="prismatic">
        <parent link="elevation_module"/>
        <child link="arm_base"/>
        <origin xyz="0.035 0 -0.0228" rpy="0 0 0"/>
        <axis xyz="1 0 0"/>
        <limit lower="-0.15" upper="0" velocity="0.06" effort="20"/>
    </joint>
    <xacro:insert_position_transmission name="arm_base_joint" />

    <link name="arm_link1">
        <visual>
            <origin xyz="0 0 0" rpy="0 0 0"/>
            <geometry>
                <mesh filename="package://living_lab_robot_description/meshes/arm_link1.dae" scale="1 1 1"/>
            </geometry>
        </visual>
        <collision>
            <origin xyz="0 0 0" rpy="0 0 0"/>
            <geometry>
                <mesh filename="package://living_lab_robot_description/meshes/arm_link1.dae" scale="1 1 1"/>
            </geometry>
        </collision>
        <inertial>
            <origin xyz="0.0330 0 0" rpy="0 0 0"/>
            <mass value="0.5067"/>
            <inertia ixx="0.001238" ixy="0.0" ixz="0.0" iyy="0.000376" iyz="0.0" izz="0.001238"/>
        </inertial>
    </link>

    <joint name="arm1_joint" type="revolute">
        <parent link="arm_base"/>
        <child link="arm_link1"/>
        <origin xyz="0.15612 0 -0.051215" rpy="0 0 0"/>
        <axis xyz="1 0 0"/>
        <limit lower="${-180/180*pi}" upper="${180/180*pi}" velocity="1.0" effort="20"/>
    </joint>
    <xacro:insert_position_transmission name="arm1_joint" />

    <link name="arm_link2">
        <visual>
            <origin xyz="0 0 0" rpy="0 0 0"/>
            <geometry>
                <mesh filename="package://living_lab_robot_description/meshes/arm_link2.dae" scale="1 1 1"/>
            </geometry>
        </visual>
        <collision>
            <origin xyz="0 0 0" rpy="0 0 0"/>
            <geometry>
                <mesh filename="package://living_lab_robot_description/meshes/arm_link2.dae" scale="1 1 1"/>
            </geometry>
        </collision>
        <inertial>
            <origin xyz="0.1642 0 0.0083" rpy="0 0 0"/>
            <mass value="1.1597"/>
            <inertia ixx="0.005197" ixy="0" ixz="-0.001920" iyy="0.017977" iyz="0" izz="0.020790"/>
        </inertial>
    </link>

    <joint name="arm2_joint" type="revolute">
        <parent link="arm_link1"/>
        <child link="arm_link2"/>
        <origin xyz="0.033 0 0" rpy="0 0 0"/>
        <axis xyz="0 1 0"/>
        <limit lower="${-95/180*pi}" upper="${95/180*pi}" velocity="1.0" effort="20"/>
    </joint>
    <xacro:insert_position_transmission name="arm2_joint" />

    <link name="arm_link3">
        <visual>
            <origin xyz="0 0 0" rpy="0 0 0"/>
            <geometry>
                <mesh filename="package://living_lab_robot_description/meshes/arm_link3.dae" scale="1 1 1"/>
            </geometry>
        </visual>
        <collision>
            <origin xyz="0 0 0" rpy="0 0 0"/>
            <geometry>
                <mesh filename="package://living_lab_robot_description/meshes/arm_link3.dae" scale="1 1 1"/>
            </geometry>
        </collision>
        <inertial>
            <origin xyz="0.1137 0 -0.0409" rpy="0 0 0"/>
            <mass value="1.1757"/>
            <inertia ixx="0.001933" ixy="0" ixz="0" iyy="0.005040" iyz="0.0" izz="0.006220"/>
        </inertial>
    </link>

    <joint name="arm3_joint" type="revolute">
        <parent link="arm_link2"/>
        <child link="arm_link3"/>
        <origin xyz="0.264 0 0.030" rpy="0 0 0"/>
        <axis xyz="0 1 0"/>
        <limit lower="${-180/180*pi}" upper="${5/180*pi}" velocity="1.0" effort="20"/>
    </joint>
    <xacro:insert_position_transmission name="arm3_joint" />

    <link name="arm_link4">
        <visual>
            <origin xyz="0 0 0" rpy="0 0 0"/>
            <geometry>
                <mesh filename="package://living_lab_robot_description/meshes/arm_link4.dae" scale="1 1 1"/>
            </geometry>
        </visual>
        <collision>
            <origin xyz="0 0 0" rpy="0 0 0"/>
            <geometry>
                <mesh filename="package://living_lab_robot_description/meshes/arm_link4.dae" scale="1 1 1"/>
            </geometry>
        </collision>
        <inertial>
            <origin xyz="0.0269 0.0 0.0" rpy="0 0 0"/>
            <mass value="0.2697"/>
            <inertia ixx="0.000422" ixy="0.0" ixz="0.0" iyy="0.000133" iyz="0.0" izz="0.000422"/>
        </inertial>
    </link>

    <joint name="arm4_joint" type="revolute">
        <parent link="arm_link3"/>
        <child link="arm_link4"/>
        <origin xyz="0.231 0 -0.042" rpy="0 0 0"/>
        <axis xyz="1 0 0"/>
        <limit lower="${-180/180*pi}" upper="${180/180*pi}" velocity="1.0" effort="20"/>
    </joint>
    <xacro:insert_position_transmission name="arm4_joint" />

    <link name="arm_link5">
        <visual>
            <origin xyz="0 0 0" rpy="0 0 0"/>
            <geometry>
                <mesh filename="package://living_lab_robot_description/meshes/arm_link5.dae" scale="1 1 1"/>
            </geometry>
        </visual>
        <collision>
            <origin xyz="0 0 0" rpy="0 0 0"/>
            <geometry>
                <mesh filename="package://living_lab_robot_description/meshes/arm_link5.dae" scale="1 1 1"/>
            </geometry>
        </collision>
        <inertial>
            <origin xyz="0.0667 0 -0.0005" rpy="0 0 0"/>
            <mass value="0.3885"/>
            <inertia ixx="0.000462" ixy="0.0" ixz="0.0" iyy="0.000460" iyz="0.0" izz="0.000781"/>
        </inertial>
    </link>

    <joint name="arm5_joint" type="revolute">
        <parent link="arm_link4"/>
        <child link="arm_link5"/>
        <origin xyz="0.027 0 0" rpy="0 0 0"/>
        <axis xyz="0 1 0"/>
        <limit lower="${-95/180*pi}" upper="${95/180*pi}" velocity="1.0" effort="20"/>
    </joint>
    <xacro:insert_position_transmission name="arm5_joint" />

    <link name="arm_link6">
        <visual>
            <origin xyz="0 0 0" rpy="0 0 0"/>
            <geometry>
                <mesh filename="package://living_lab_robot_description/meshes/arm_link6.dae" scale="1 1 1"/>
            </geometry>
        </visual>
        <collision>
            <origin xyz="0 0 0" rpy="0 0 0"/>
            <geometry>
                <mesh filename="package://living_lab_robot_description/meshes/arm_link6.dae" scale="1 1 1"/>
            </geometry>
        </collision>
        <inertial>
            <origin xyz="-0.0030 0 0" rpy="0 0 0"/>
            <mass value="0.0038"/>
            <inertia ixx="0.0000006" ixy="0.0" ixz="0.0" iyy="0.0000003" iyz="0.0" izz="0.0000003"/>
        </inertial>
    </link>

    <joint name="arm6_joint" type="revolute">
        <parent link="arm_link5"/>
        <child link="arm_link6"/>
        <origin xyz="0.123 0 0" rpy="0 0 0"/>
        <axis xyz="1 0 0"/>
        <limit lower="${-180/180*pi}" upper="${180/180*pi}" velocity="1.0" effort="20"/>
    </joint>
    <xacro:insert_position_transmission name="arm6_joint" />
</robot>