<?xml version="1.0"?>
<robot xmlns:xacro="http://www.ros.org/wiki/xacro">
    <link name="body_assy">
        <visual>
            <origin xyz="0 0 0" rpy="0 0 0"/>
            <geometry>
                <mesh filename="package://living_lab_robot_description/meshes/body_assy.dae" scale="1 1 1"/>
            </geometry>
        </visual>
        <collision>
            <origin xyz="0 0 0" rpy="0 0 0"/>
            <geometry>
                <mesh filename="package://living_lab_robot_description/meshes/body_assy.dae" scale="1 1 1"/>
            </geometry>
        </collision>
        <inertial>
            <origin xyz="0 0 0.3780" rpy="0 0 0"/>
            <mass value="3.21"/>
            <inertia ixx="0.263797" ixy="0.000014" ixz="-0.000365" iyy="0.255334" iyz="-0.000303" izz="0.069846"/>
        </inertial>
    </link>

    <joint name="body_rotate_joint" type="revolute">
        <parent link="base_link"/>
        <child link="body_assy"/>
        <origin xyz="0 0 0.242" rpy="0 0 0"/>
        <axis xyz="0 0 1"/>
        <limit lower="${-200/180*pi}" upper="${200/180*pi}" velocity="0.4" effort="1000"/>
    </joint>
    <xacro:insert_position_transmission name="body_rotate_joint" />

    <link name="elevation_module">
        <visual>
            <origin xyz="0 0 0" rpy="0 0 0"/>
            <geometry>
                <mesh filename="package://living_lab_robot_description/meshes/elevation_module.dae" scale="1 1 1"/>
            </geometry>
        </visual>
        <collision>
            <origin xyz="0 0 0" rpy="0 0 0"/>
            <geometry>
                <mesh filename="package://living_lab_robot_description/meshes/elevation_module.dae" scale="1 1 1"/>
            </geometry>
        </collision>
        <inertial>
            <origin xyz="0 0 0" rpy="0 0 0"/>
            <mass value="0.31"/>
            <inertia ixx="0.001422" ixy="0.000007" ixz="0.000024" iyy="0.000917" iyz="-0.000039" izz="0.001769"/>
        </inertial>
    </link>

    <joint name="elevation_joint" type="prismatic">
        <parent link="body_assy"/>
        <child link="elevation_module"/>
        <origin xyz="-0.05 0 0.665" rpy="0 0 0"/>
        <axis xyz="0 0 1"/>
        <limit lower="-0.45" upper="0" velocity="0.08" effort="1000"/>
    </joint>
    <xacro:insert_position_transmission name="elevation_joint" />
</robot>