<?xml version="1.0"?>
<robot xmlns:xacro="http://www.ros.org/wiki/xacro">
    <xacro:include filename="$(find realsense2_description)/urdf/_d435.urdf.xacro" />

    <link name="head_assy">
        <visual>
            <origin xyz="0 0 0" rpy="0 0 0"/>
            <geometry>
                <mesh filename="package://living_lab_robot_description/meshes/head_assy.dae" scale="1 1 1"/>
            </geometry>
        </visual>
        <collision>
            <origin xyz="0 0 0" rpy="0 0 0"/>
            <geometry>
                <mesh filename="package://living_lab_robot_description/meshes/head_assy.dae" scale="1 1 1"/>
            </geometry>
        </collision>
        <inertial>
            <origin xyz="0 0 -0.1224" rpy="0 0 0"/>
            <mass value="6.545411"/>
            <inertia ixx="0.085366" ixy="0.0" ixz="0.0" iyy="0.085366" iyz="0.0" izz="0.105357"/>
        </inertial>
    </link>

    <joint name="head_pan_joint" type="revolute">
        <parent link="body_assy"/>
        <child link="head_assy"/>
        <origin xyz="0 0 0.983" rpy="0 0 0"/>
        <axis xyz="0 0 1"/>
        <limit lower="${-270/180*pi}" upper="${270/180*pi}" velocity="2.0" effort="1000"/>
    </joint>
    <xacro:insert_position_transmission name="head_pan_joint" />

    <link name="head_screen">
        <visual>
            <origin xyz="0 0 0" rpy="0 0 0"/>
            <geometry>
                <mesh filename="package://living_lab_robot_description/meshes/head_screen.dae" scale="1 1 1"/>
            </geometry>
        </visual>
        <collision>
            <origin xyz="0 0 0" rpy="0 0 0"/>
            <geometry>
                <mesh filename="package://living_lab_robot_description/meshes/head_screen.dae" scale="1 1 1"/>
            </geometry>
        </collision>
        <inertial>
            <origin xyz="0.014478 0.0 -0.045490" rpy="0 0 0"/>
            <mass value="0.186690"/>
            <inertia ixx="0.000811" ixy="0.0" ixz="0.000012" iyy="0.000271" iyz="0.0" izz="0.000576"/>
        </inertial>
    </link>

    <joint name="head_screen_tilt_joint" type="revolute">
        <parent link="head_assy"/>
        <child link="head_screen"/>
        <origin xyz="0.101 0 -0.112" rpy="0 0 0"/>
        <axis xyz="0 1 0"/>
        <limit lower="${-10/180*pi}" upper="${5/180*pi}" velocity="2.0" effort="1000"/>
    </joint>
    <xacro:insert_position_transmission name="head_screen_tilt_joint" />

    <link name="head_tilt_unit">
        <visual>
            <origin xyz="0 0 0" rpy="0 0 0"/>
            <geometry>
                <mesh filename="package://living_lab_robot_description/meshes/head_tilt_unit.dae" scale="1 1 1"/>
            </geometry>
        </visual>
        <collision>
            <origin xyz="0 0 0" rpy="0 0 0"/>
            <geometry>
                <mesh filename="package://living_lab_robot_description/meshes/head_tilt_unit.dae" scale="1 1 1"/>
            </geometry>
        </collision>
        <inertial>
            <origin xyz="-0.098000 0 0.057616" rpy="0 0 0"/>
            <mass value="2.540090"/>
            <inertia ixx="0.022353" ixy="0.0" ixz="0.0" iyy="0.022353" iyz="0.0" izz="0.040886"/>
        </inertial>
    </link>

    <joint name="head_tilt_joint" type="revolute">
        <parent link="head_assy"/>
        <child link="head_tilt_unit"/>
        <origin xyz="0.098 0 -0.016" rpy="0 0 0"/>
        <axis xyz="0 1 0"/>
        <limit lower="${0/180*pi}" upper="${40/180*pi}" velocity="0.2" effort="1000"/>
    </joint>
    <xacro:insert_position_transmission name="head_tilt_joint" />

    <xacro:sensor_d435 parent="head_tilt_unit">
        <origin xyz="0.0172 0 0.0185" rpy="0 0 0"/>
    </xacro:sensor_d435>
    <xacro:insert_rgbd_camera_sensor name="camera"/>

    <link name="gaze_link">
        <!-- <inertial>
            <origin xyz="0 0 0" rpy="0 0 0"/>
            <mass value="0.01"/>
            <inertia ixx="0.0001" ixy="0.0" ixz="0.0" iyy="0.0001" iyz="0.0" izz="0.0001"/>
        </inertial> -->
    </link>

    <joint name="gaze_fixed_joint" type="fixed">
        <parent link="head_assy"/>
        <child link="gaze_link"/>
        <origin xyz="0.1 0 0.0185" rpy="0 0 0"/>
    </joint>
</robot>